Workbook

Sheet 분석
B1: NPL 투자수익률 계산기
F2: 매각기일 | G2: =G3+365
B3: 사건번호 | F3: 채권매입예상일 | G3: =TODAY()+365
B4: 주소 | F4: 투자기간(일) | G4: =DATEDIF(G3,E7,"D")
B5: 용도 | D5: 지목 | F5: 근저당이전비용 | G5: =E8*C22+C24+E8*C23
B6: 토지면적 | D6: 경매개시일 | F6: 질권대출LTV | G6: 0.75
B7: 건물면적 | D7: 예상배당일 | E7: =G2+45 | F7: 질권대출금리 | G7: 0.0613
B8: 채권은행 | D8: 채권최고액 | F8: 질권대출금액 | G8: =E20*G6
B9: 담당자 | D9: 원금 | F9: 근질권설정비용 | G9: =IF(G6=0, 0, G8*1.3*C25+C24+350000) | J9: =G8*1.3
B10: 연락처 | D10: 연체이자(기준일자) | F10: 총근질권대출이자 | G10: =G8*G7/365*DATEDIF(G3,E7,"D")
B11: 기준일시 | D11: 연체금리 | F11: 초기투자금(계약시) | G11: =E20+G5+G9-G8+C17
B12: 소유자/채무자 | D12: 추가연체이자 | E12: =E9*E11/365*DATEDIF(C11,E7,"D") | F12: 총투자금(근질권대출이자포함) | G12: =G11+G10
B13: 감정평가금액 | D13: 연체이자총액 | E13: =E10+E12 | F13: 총수익금 | G13: =E16-G12-G8+C17
B14: 예상낙찰가율 | C14: 0.7 | D14: 예상권리가액 | E14: =MIN(E8,E9+E13) | F14: 자기자본수익률(ROE) | G14: =G13/G12
B15: 예상낙찰가 | C15: =C13*C14 | D15: 대부법인이용수수료 | F15: 연수익률 | G15: =G14*365/G4
B16: 선순위금액 | C16: 0 | D16: 배당추정금액 | E16: =MIN(E14,(C15-C16-C18-C19-C20)) | F16: 채권매입외비용 | G16: =C17+E15+G5+G9+G10
B17: 가지급금 | D17: 채권매입비율(원금대비) | E17: 0.89 | F17: 유입시 총 비용,취득세등 비용포함 | G17: =(C15-E16)+C27+C28+E20+G5+G9+G10+'법인세 부가세 취득세'!C24-'법인세 부가세 취득세'!C16
B18: 경매비용 | C18: 0 | D18: 채권매입비율(원금+연체) | E18: 0.89
B19: 소액임차최우선변제금
B20: 당해세 | C20: 0 | D20: 채권매입금액 (원금 or 연체포함) | E20: =MAX((E9*E17),((E9+E10)*E18))
B21: *가지급금제외
B22: *근저당이전비용 | C22: 0.0024
B23: 국민주택채권 | C23: 0.0015
B24: 법무비/인지세/기타 | C24: 1500000
B25: *질권설정비용 | C25: 0.0024
B26: *대부법인이용수수료 | C26: 0.0067
B27: 취득시 법무비용 | C27: 1000000
B28: 취득시 공인중개사비용 | C28: 0
B30: 감정평가 합계 | C30: =C13 | E30: 대표자
B31: 감정 평가 토지분 | E31: 주소
B32: 감정평가 건물분 | E32: 연락처
B33: 감정 평가 제시외 건물 | E33: 사업자 등록번호
B34: 총건물 면적 | E34: 채무자 주소
B35: 주거 | E35: 계약일
B36: 근린 | C36: =SUM(C39:C44)
B37: 토지 (대지) 면적
B39: 지하 1층 근린 | C39: 0
B40: 1층 근린 | C40: 0
B41: 2층 근린 | C41: 0
B42: 3층 근린 | C42: 0
...

Sheet 법인세 부가세 취득세
B2: 법인이 직접 투자
B3: 기존 당기순이익 | C3: 200000000 | D3: 세전 순수익 (A) | E3: =C4 - C5 - (C5*C6*C7*(C8/365)) - C9
B4: 이번 NPL 배당금 | C4: =분석!E16 | D4: 법인세 합계 | E4: =IF(C3>=200000000, E3*0.22, IF(C3+E3<=200000000, E3*0.11, (200000000-C3)*0.11 + (C3+E3-200000000)*0.22))
B5: 채권 매입가 | C5: =분석!E20 | D5: 최종 세후 순수익 | E5: =E3-E4
B6: 질권대출 LTV | C6: 0.75
B7: 질권대출 연금리 | C7: =분석!G7
B8: 투자 기간 (일수) | C8: =분석!G4
B9: 기타 제비용 | C9: =분석!G16-분석!G10
B10: 법인세율 | C10: =IF(C3>=200000000, 0.2, IF(C3<=200000000, 0.1, (200000000-C3)*0.11 + (C3+E3-200000000)*0.2))
B11: 지방소득세율 | C11: =C10*0.1
B12: 질권대출 이자 | C12: =ROUND(C5 * C6 * C7 * (C8/365), 0)
B13: 부가세 환급 상세 | D13: 직접 유입 여부 | E13: 1
B14: 기준시가 토지분 | C14: 0 | D14: ※ 0 입력 시 감정평가 기준 적용
B15: 기준시가 건물분 | C15: 0 | D15: ※ E13: 1=직접유입, 0=제3자낙찰
B16: 부가세 환급 | C16: 0
B17: 감정평가 | C17: =분석!C30
B18: 낙찰가 (예상) | C18: =분석!C15
B19: 토지분 | C19: 0
B20: 건물분 | C20: 0
B21: 낙찰가 건물 안분액 | C21: =IF(AND(C14>0,C15>0), C18*C15/(C14+C15), IF(C17=0, 0, C18*C20/C17)) | D21: 안분기준 | E21: =IF(AND(C14>0,C15>0), "기준시가", "감정평가")
B22: 상가 건물분 (과세대상) | C22: =IF(OR(C21=0, 분석!C34=0), 0, C21*분석!C36/분석!C34) | D22: 근린비율 | E22: =IF(분석!C34=0, 0, 분석!C36/분석!C34)
B23: 주거+제시외 건물분 (면세) | C23: =C21-C22 | D23: 주거비율 | E23: =IF(분석!C34=0, 0, (분석!C35+분석!C45)/분석!C34)
B24: 취득세 합계 | C24: =C39+D39+E39
B25: 감정평가 | C25: =분석!C13
B26: 과세표준 (낙찰가) | C26: =C18
B27: 주거 과세표준 | C27: =IF(OR(C17=0,분석!C34=0),0,C26/C17*(분석!C32*분석!C35/분석!C34+IF(C30=1,분석!C33,0))) | D27: 비율 | E27: =IF(C26=0,0,C27/C26)
B28: 상가 과세표준 | C28: =IF(OR(C17=0,분석!C34=0),0,C26/C17*(분석!C32*분석!C36/분석!C34+IF(C30=0,분석!C33,0))) | D28: 비율 | E28: =IF(C26=0,0,C28/C26)
B29: 토지 과세표준 | C29: =C26-C27-C28
B30: 제시외 건물 분류 | C30: 0 | D30: ※ 0=상가, 1=주거 (옥탑/다락=주거)
B31: 검증(과세표준 합계) | C31: =C27+C28+C29 | D31: =IF(ABS(C31-C26)<1,"OK","ERROR")
B32: 취득세 세부 내역
B33: 구분 | C33: 주거부분 | D33: 상가부분 | E33: 토지부분 | F33: 비고
B34: 취득세율 (본세) | C34: 0.12 | D34: 0.04 | E34: 0.04 | F34: 토지 4%
B35: 취득세 (본세) | C35: =C27*C34 | D35: =(C28+C30)*D34 | E35: =C29*E34
B36: 지방교육세 | C36: =C35*0.1 | D36: =D35*0.1 | E36: =E35*0.1 | F36: 취득세 본세 × 10%
B37: 농특세율 | C37: 0.002 | D37: 0.002 | E37: 0.002 | F37: 85m²초과 0.2%
B38: 농어촌특별세 | C38: =C27*C37 | D38: =(C28+C30)*D37 | E38: =(C25-C27-C28)*E37
B39: 소계 | C39: =C35+C36+C38 | D39: =D35+D36+D38 | E39: =E35+E36+E38
B40: 합산세율 | C40: =C34+C34*0.1+C37 | D40: =D34+D34*0.1+D37 | E40: =E34+E34*0.1+E37
